Workbook

Sheet Model
B1: HB 1336 — Third-Party Deposit-Assistance Capital Model (v2)
B2: Incremental impact of HB 1336 on private charitable deposit-assistance capital. Baseline = do nothing (charity funds standard deposits as one-way grants; RCDs do not exist). Policy = HB 1336 passes (charity funds deposit + RCD where needed, both refundable to the third-party payor and recycled).
B4: INPUTS — Funding & deployment (edit blue cells)
B5: Annual charitable inflow (gross) | C5: 1000000 | D5: Donations raised per year before overhead
B6: Overhead / admin rate | C6: 0.3 | D6: Share of gross consumed by fundraising & administration
B7: Net new capital per year | C7: =C5*(1-C6) | D7: inflow × (1 − overhead)
B8: Average security deposit (≈ 1 month rent) | C8: 2000 | D8: Capped at 1 month rent under RSA 540-A:6 (existing law)
B9: RCD size as multiple of standard deposit | C9: 1 | D9: HB 1336 caps RCD at one ADDITIONAL month of rent → 1.0×
B10: % of assisted households requiring BOTH deposit + RCD | C10: 0.3 | D10: Many applicants need only deposit help; subset also fails one of the 5 statutory criteria
B11: Average capital deployed per assisted household | C11: =C8*(1+C10*C9) | D11: deposit × (1 + bundle% × RCD multiple)
B12: Average tenancy before refund (yrs) [L] | C12: 3 | D12: Whole years 1–5; longer L = slower recycling (more conservative)
B13: Apply overhead to recycled capital? | C13: No | D13: No = recycled dollars need no re-fundraising
B14: Recycle factor | C14: =IF(C13="Yes",1-C6,1) | D14: Multiplier applied to returning capital
B16: RECOVERY RATE — anchored to TransUnion ResidentScore tiers
B17: Recovery method ("Tier-weighted" or "Manual override") | C17: Tier-weighted | D17: Type "Manual override" in B17 to use the flat r below instead of the tier-weighted calc
B18: Manual override recovery rate r (used only if Manual override) | C18: 0.7 | D18: Falls back to the original v1 default of 70% for very-conservative scenarios
B19: Loss-given-eviction (share of held deposit + RCD consumed when eviction occurs) | C19: 1 | D19: 100% = full impound when an eviction is filed and reduced to judgment
B20: Base non-recovery (lawful deductions absent eviction — wear, cleaning, damages) | C20: 0.15 | D20: Average across non-evicted tenancies; 5–15% is a defensible range
B21: Population-weighted eviction rate | C21: =SUMPRODUCT(C26:C30,D26:D30) | D21: From credit-tier table below; depends on the population mix you assume
B22: Effective recovery rate r (used in year-by-year model) | C22: =IF(C17="Manual override",C18,MAX(0,1-C21*C19-C20)) | D22: r = 1 − (weighted eviction × LGE) − base non-recovery
B24: Credit-tier reference (TransUnion ResidentScore — see v9 Policy Analysis §3)
B25: ResidentScore tier | C25: Eviction rate | D25: Population mix (edit to match served population)
B26: 350–449 | C26: 0.123 | D26: 0.05
B27: 450–499 | C27: 0.094 | D27: 0.15
B28: 500–549 | C28: 0.058 | D28: 0.35
B29: 550–649 | C29: 0.013 | D29: 0.35
B30: 650–749 | C30: 0.003 | D30: 0.1
B31: Population mix total (must equal 100%) | D31: =SUM(D26:D30)
B33: RESULTS — 10-year horizon (do nothing vs. HB 1336 passes)
B34: Cumulative households — DO NOTHING (grant, deposit-only) | C34: =H52
B35: Cumulative households — HB 1336 PASSES (revolving, deposit + RCD where needed) | C35: =E52
B36: Incremental households from HB 1336 | C36: =C35-C34
B37: Reach multiplier (HB 1336 ÷ do nothing) | C37: =C35/C34
B38: Year-10 annual capacity — do nothing | C38: =G52
B39: Year-10 annual capacity — HB 1336 | C39: =D52
B41: YEAR-BY-YEAR
B42: Year | C42: HB 1336: capital deployed | D42: HB 1336: households | E42: HB 1336: cumulative HH | F42: Do nothing: grant capital | G42: Do nothing: households | H42: Do nothing: cumulative HH
B43: 1 | C43: =$C$7+IF(B43>$C$12,$C$14*$C$22*OFFSET(B43,-$C$12,1),0) | D43: =C43/$C$11 | E43: =D43 | F43: =$C$7 | G43: =F43/$C$8 | H43: =G43
B44: 2 | C44: =$C$7+IF(B44>$C$12,$C$14*$C$22*OFFSET(B44,-$C$12,1),0) | D44: =C44/$C$11 | E44: =E43+D44 | F44: =$C$7 | G44: =F44/$C$8 | H44: =H43+G44
B45: 3 | C45: =$C$7+IF(B45>$C$12,$C$14*$C$22*OFFSET(B45,-$C$12,1),0) | D45: =C45/$C$11 | E45: =E44+D45 | F45: =$C$7 | G45: =F45/$C$8 | H45: =H44+G45
...

Sheet Sensitivity
A1: Sensitivity — incremental impact of HB 1336 vs. do-nothing baseline (DYNAMIC: every cell recomputes from current Model inputs)
A2: Do-nothing baseline: charity funds standard deposits as one-way grants; RCDs do not exist; no recovery applies, so baseline = (net new capital × 10 years) ÷ deposit. HB 1336 baseline: revolving fund supports deposit + RCD where needed, both refundable under §540-A:7, I(b) and recycled.
A3: In tables 1–3, recovery rate r and tenancy L apply to HB 1336 only. The do-nothing baseline is independent of r (no recycling possible without §540-A:7, I(b)).
A4: Live do-nothing baseline (households / 10 yrs): | B4: =Model!$C$7*10/Model!$C$8
A6: Table 1 — Reach multiplier (HB 1336 ÷ do nothing) at the model's current bundle %
A7: HB 1336 recovery r \ tenancy L | B7: 1 | C7: 2 | D7: 3 | E7: 4
A8: 0.5 | B8: =Model!$C$7/(1-$A8)*(10-SUMPRODUCT(POWER($A8,INT((ROW(INDIRECT("1:10"))-1)/B$7)+1)))/Model!$C$11/(Model!$C$7*10/Model!$C$8) | C8: =Model!$C$7/(1-$A8)*(10-SUMPRODUCT(POWER($A8,INT((ROW(INDIRECT("1:10"))-1)/C$7)+1)))/Model!$C$11/(Model!$C$7*10/Model!$C$8) | D8: =Model!$C$7/(1-$A8)*(10-SUMPRODUCT(POWER($A8,INT((ROW(INDIRECT("1:10"))-1)/D$7)+1)))/Model!$C$11/(Model!$C$7*10/Model!$C$8) | E8: =Model!$C$7/(1-$A8)*(10-SUMPRODUCT(POWER($A8,INT((ROW(INDIRECT("1:10"))-1)/E$7)+1)))/Model!$C$11/(Model!$C$7*10/Model!$C$8)
A9: 0.6 | B9: =Model!$C$7/(1-$A9)*(10-SUMPRODUCT(POWER($A9,INT((ROW(INDIRECT("1:10"))-1)/B$7)+1)))/Model!$C$11/(Model!$C$7*10/Model!$C$8) | C9: =Model!$C$7/(1-$A9)*(10-SUMPRODUCT(POWER($A9,INT((ROW(INDIRECT("1:10"))-1)/C$7)+1)))/Model!$C$11/(Model!$C$7*10/Model!$C$8) | D9: =Model!$C$7/(1-$A9)*(10-SUMPRODUCT(POWER($A9,INT((ROW(INDIRECT("1:10"))-1)/D$7)+1)))/Model!$C$11/(Model!$C$7*10/Model!$C$8) | E9: =Model!$C$7/(1-$A9)*(10-SUMPRODUCT(POWER($A9,INT((ROW(INDIRECT("1:10"))-1)/E$7)+1)))/Model!$C$11/(Model!$C$7*10/Model!$C$8)
A10: 0.7 | B10: =Model!$C$7/(1-$A10)*(10-SUMPRODUCT(POWER($A10,INT((ROW(INDIRECT("1:10"))-1)/B$7)+1)))/Model!$C$11/(Model!$C$7*10/Model!$C$8) | C10: =Model!$C$7/(1-$A10)*(10-SUMPRODUCT(POWER($A10,INT((ROW(INDIRECT("1:10"))-1)/C$7)+1)))/Model!$C$11/(Model!$C$7*10/Model!$C$8) | D10: =Model!$C$7/(1-$A10)*(10-SUMPRODUCT(POWER($A10,INT((ROW(INDIRECT("1:10"))-1)/D$7)+1)))/Model!$C$11/(Model!$C$7*10/Model!$C$8) | E10: =Model!$C$7/(1-$A10)*(10-SUMPRODUCT(POWER($A10,INT((ROW(INDIRECT("1:10"))-1)/E$7)+1)))/Model!$C$11/(Model!$C$7*10/Model!$C$8)
A11: 0.8 | B11: =Model!$C$7/(1-$A11)*(10-SUMPRODUCT(POWER($A11,INT((ROW(INDIRECT("1:10"))-1)/B$7)+1)))/Model!$C$11/(Model!$C$7*10/Model!$C$8) | C11: =Model!$C$7/(1-$A11)*(10-SUMPRODUCT(POWER($A11,INT((ROW(INDIRECT("1:10"))-1)/C$7)+1)))/Model!$C$11/(Model!$C$7*10/Model!$C$8) | D11: =Model!$C$7/(1-$A11)*(10-SUMPRODUCT(POWER($A11,INT((ROW(INDIRECT("1:10"))-1)/D$7)+1)))/Model!$C$11/(Model!$C$7*10/Model!$C$8) | E11: =Model!$C$7/(1-$A11)*(10-SUMPRODUCT(POWER($A11,INT((ROW(INDIRECT("1:10"))-1)/E$7)+1)))/Model!$C$11/(Model!$C$7*10/Model!$C$8)
A12: 0.9 | B12: =Model!$C$7/(1-$A12)*(10-SUMPRODUCT(POWER($A12,INT((ROW(INDIRECT("1:10"))-1)/B$7)+1)))/Model!$C$11/(Model!$C$7*10/Model!$C$8) | C12: =Model!$C$7/(1-$A12)*(10-SUMPRODUCT(POWER($A12,INT((ROW(INDIRECT("1:10"))-1)/C$7)+1)))/Model!$C$11/(Model!$C$7*10/Model!$C$8) | D12: =Model!$C$7/(1-$A12)*(10-SUMPRODUCT(POWER($A12,INT((ROW(INDIRECT("1:10"))-1)/D$7)+1)))/Model!$C$11/(Model!$C$7*10/Model!$C$8) | E12: =Model!$C$7/(1-$A12)*(10-SUMPRODUCT(POWER($A12,INT((ROW(INDIRECT("1:10"))-1)/E$7)+1)))/Model!$C$11/(Model!$C$7*10/Model!$C$8)
A13: Reach multiplier > 1.0 means HB 1336 serves more households than do-nothing at those parameters. Bundle % is whatever you've set in Model!C10; do-nothing is always live cell B4 above.
A15: Table 2 — Cumulative households under HB 1336 over 10 years at the model's current bundle %
A16: HB 1336 recovery r \ tenancy L | B16: 1 | C16: 2 | D16: 3 | E16: 4
A17: 0.5 | B17: =Model!$C$7/(1-$A17)*(10-SUMPRODUCT(POWER($A17,INT((ROW(INDIRECT("1:10"))-1)/B$16)+1)))/Model!$C$11 | C17: =Model!$C$7/(1-$A17)*(10-SUMPRODUCT(POWER($A17,INT((ROW(INDIRECT("1:10"))-1)/C$16)+1)))/Model!$C$11 | D17: =Model!$C$7/(1-$A17)*(10-SUMPRODUCT(POWER($A17,INT((ROW(INDIRECT("1:10"))-1)/D$16)+1)))/Model!$C$11 | E17: =Model!$C$7/(1-$A17)*(10-SUMPRODUCT(POWER($A17,INT((ROW(INDIRECT("1:10"))-1)/E$16)+1)))/Model!$C$11
A18: 0.6 | B18: =Model!$C$7/(1-$A18)*(10-SUMPRODUCT(POWER($A18,INT((ROW(INDIRECT("1:10"))-1)/B$16)+1)))/Model!$C$11 | C18: =Model!$C$7/(1-$A18)*(10-SUMPRODUCT(POWER($A18,INT((ROW(INDIRECT("1:10"))-1)/C$16)+1)))/Model!$C$11 | D18: =Model!$C$7/(1-$A18)*(10-SUMPRODUCT(POWER($A18,INT((ROW(INDIRECT("1:10"))-1)/D$16)+1)))/Model!$C$11 | E18: =Model!$C$7/(1-$A18)*(10-SUMPRODUCT(POWER($A18,INT((ROW(INDIRECT("1:10"))-1)/E$16)+1)))/Model!$C$11
A19: 0.7 | B19: =Model!$C$7/(1-$A19)*(10-SUMPRODUCT(POWER($A19,INT((ROW(INDIRECT("1:10"))-1)/B$16)+1)))/Model!$C$11 | C19: =Model!$C$7/(1-$A19)*(10-SUMPRODUCT(POWER($A19,INT((ROW(INDIRECT("1:10"))-1)/C$16)+1)))/Model!$C$11 | D19: =Model!$C$7/(1-$A19)*(10-SUMPRODUCT(POWER($A19,INT((ROW(INDIRECT("1:10"))-1)/D$16)+1)))/Model!$C$11 | E19: =Model!$C$7/(1-$A19)*(10-SUMPRODUCT(POWER($A19,INT((ROW(INDIRECT("1:10"))-1)/E$16)+1)))/Model!$C$11
A20: 0.8 | B20: =Model!$C$7/(1-$A20)*(10-SUMPRODUCT(POWER($A20,INT((ROW(INDIRECT("1:10"))-1)/B$16)+1)))/Model!$C$11 | C20: =Model!$C$7/(1-$A20)*(10-SUMPRODUCT(POWER($A20,INT((ROW(INDIRECT("1:10"))-1)/C$16)+1)))/Model!$C$11 | D20: =Model!$C$7/(1-$A20)*(10-SUMPRODUCT(POWER($A20,INT((ROW(INDIRECT("1:10"))-1)/D$16)+1)))/Model!$C$11 | E20: =Model!$C$7/(1-$A20)*(10-SUMPRODUCT(POWER($A20,INT((ROW(INDIRECT("1:10"))-1)/E$16)+1)))/Model!$C$11
A21: 0.9 | B21: =Model!$C$7/(1-$A21)*(10-SUMPRODUCT(POWER($A21,INT((ROW(INDIRECT("1:10"))-1)/B$16)+1)))/Model!$C$11 | C21: =Model!$C$7/(1-$A21)*(10-SUMPRODUCT(POWER($A21,INT((ROW(INDIRECT("1:10"))-1)/C$16)+1)))/Model!$C$11 | D21: =Model!$C$7/(1-$A21)*(10-SUMPRODUCT(POWER($A21,INT((ROW(INDIRECT("1:10"))-1)/D$16)+1)))/Model!$C$11 | E21: =Model!$C$7/(1-$A21)*(10-SUMPRODUCT(POWER($A21,INT((ROW(INDIRECT("1:10"))-1)/E$16)+1)))/Model!$C$11
A22: Compare each cell to the do-nothing baseline in B4 (live). HB 1336 dominates do-nothing wherever cells in this table exceed the B4 baseline.
A24: Table 3 — Bundling sensitivity: 10-year cumulative HH under HB 1336 vs. (bundle %, recovery r) at the model's current L
A25: Bundle % is varied here independently of Model!C10 so you can see the full surface. r is the HB 1336 recovery rate (does not apply to do nothing). L is taken from the model (Model!C12).
A27: Bundle % \ HB 1336 recovery r | B27: 0.5 | C27: 0.6 | D27: 0.7 | E27: 0.8 | F27: 0.9
A28: 0 | B28: =Model!$C$7/(1-B$27)*(10-SUMPRODUCT(POWER(B$27,INT((ROW(INDIRECT("1:10"))-1)/Model!$C$12)+1)))/(Model!$C$8*(1+$A28*Model!$C$9)) | C28: =Model!$C$7/(1-C$27)*(10-SUMPRODUCT(POWER(C$27,INT((ROW(INDIRECT("1:10"))-1)/Model!$C$12)+1)))/(Model!$C$8*(1+$A28*Model!$C$9)) | D28: =Model!$C$7/(1-D$27)*(10-SUMPRODUCT(POWER(D$27,INT((ROW(INDIRECT("1:10"))-1)/Model!$C$12)+1)))/(Model!$C$8*(1+$A28*Model!$C$9)) | E28: =Model!$C$7/(1-E$27)*(10-SUMPRODUCT(POWER(E$27,INT((ROW(INDIRECT("1:10"))-1)/Model!$C$12)+1)))/(Model!$C$8*(1+$A28*Model!$C$9)) | F28: =Model!$C$7/(1-F$27)*(10-SUMPRODUCT(POWER(F$27,INT((ROW(INDIRECT("1:10"))-1)/Model!$C$12)+1)))/(Model!$C$8*(1+$A28*Model!$C$9))
A29: 0.25 | B29: =Model!$C$7/(1-B$27)*(10-SUMPRODUCT(POWER(B$27,INT((ROW(INDIRECT("1:10"))-1)/Model!$C$12)+1)))/(Model!$C$8*(1+$A29*Model!$C$9)) | C29: =Model!$C$7/(1-C$27)*(10-SUMPRODUCT(POWER(C$27,INT((ROW(INDIRECT("1:10"))-1)/Model!$C$12)+1)))/(Model!$C$8*(1+$A29*Model!$C$9)) | D29: =Model!$C$7/(1-D$27)*(10-SUMPRODUCT(POWER(D$27,INT((ROW(INDIRECT("1:10"))-1)/Model!$C$12)+1)))/(Model!$C$8*(1+$A29*Model!$C$9)) | E29: =Model!$C$7/(1-E$27)*(10-SUMPRODUCT(POWER(E$27,INT((ROW(INDIRECT("1:10"))-1)/Model!$C$12)+1)))/(Model!$C$8*(1+$A29*Model!$C$9)) | F29: =Model!$C$7/(1-F$27)*(10-SUMPRODUCT(POWER(F$27,INT((ROW(INDIRECT("1:10"))-1)/Model!$C$12)+1)))/(Model!$C$8*(1+$A29*Model!$C$9))
A30: 0.5 | B30: =Model!$C$7/(1-B$27)*(10-SUMPRODUCT(POWER(B$27,INT((ROW(INDIRECT("1:10"))-1)/Model!$C$12)+1)))/(Model!$C$8*(1+$A30*Model!$C$9)) | C30: =Model!$C$7/(1-C$27)*(10-SUMPRODUCT(POWER(C$27,INT((ROW(INDIRECT("1:10"))-1)/Model!$C$12)+1)))/(Model!$C$8*(1+$A30*Model!$C$9)) | D30: =Model!$C$7/(1-D$27)*(10-SUMPRODUCT(POWER(D$27,INT((ROW(INDIRECT("1:10"))-1)/Model!$C$12)+1)))/(Model!$C$8*(1+$A30*Model!$C$9)) | E30: =Model!$C$7/(1-E$27)*(10-SUMPRODUCT(POWER(E$27,INT((ROW(INDIRECT("1:10"))-1)/Model!$C$12)+1)))/(Model!$C$8*(1+$A30*Model!$C$9)) | F30: =Model!$C$7/(1-F$27)*(10-SUMPRODUCT(POWER(F$27,INT((ROW(INDIRECT("1:10"))-1)/Model!$C$12)+1)))/(Model!$C$8*(1+$A30*Model!$C$9))
A31: 0.75 | B31: =Model!$C$7/(1-B$27)*(10-SUMPRODUCT(POWER(B$27,INT((ROW(INDIRECT("1:10"))-1)/Model!$C$12)+1)))/(Model!$C$8*(1+$A31*Model!$C$9)) | C31: =Model!$C$7/(1-C$27)*(10-SUMPRODUCT(POWER(C$27,INT((ROW(INDIRECT("1:10"))-1)/Model!$C$12)+1)))/(Model!$C$8*(1+$A31*Model!$C$9)) | D31: =Model!$C$7/(1-D$27)*(10-SUMPRODUCT(POWER(D$27,INT((ROW(INDIRECT("1:10"))-1)/Model!$C$12)+1)))/(Model!$C$8*(1+$A31*Model!$C$9)) | E31: =Model!$C$7/(1-E$27)*(10-SUMPRODUCT(POWER(E$27,INT((ROW(INDIRECT("1:10"))-1)/Model!$C$12)+1)))/(Model!$C$8*(1+$A31*Model!$C$9)) | F31: =Model!$C$7/(1-F$27)*(10-SUMPRODUCT(POWER(F$27,INT((ROW(INDIRECT("1:10"))-1)/Model!$C$12)+1)))/(Model!$C$8*(1+$A31*Model!$C$9))
A32: 1 | B32: =Model!$C$7/(1-B$27)*(10-SUMPRODUCT(POWER(B$27,INT((ROW(INDIRECT("1:10"))-1)/Model!$C$12)+1)))/(Model!$C$8*(1+$A32*Model!$C$9)) | C32: =Model!$C$7/(1-C$27)*(10-SUMPRODUCT(POWER(C$27,INT((ROW(INDIRECT("1:10"))-1)/Model!$C$12)+1)))/(Model!$C$8*(1+$A32*Model!$C$9)) | D32: =Model!$C$7/(1-D$27)*(10-SUMPRODUCT(POWER(D$27,INT((ROW(INDIRECT("1:10"))-1)/Model!$C$12)+1)))/(Model!$C$8*(1+$A32*Model!$C$9)) | E32: =Model!$C$7/(1-E$27)*(10-SUMPRODUCT(POWER(E$27,INT((ROW(INDIRECT("1:10"))-1)/Model!$C$12)+1)))/(Model!$C$8*(1+$A32*Model!$C$9)) | F32: =Model!$C$7/(1-F$27)*(10-SUMPRODUCT(POWER(F$27,INT((ROW(INDIRECT("1:10"))-1)/Model!$C$12)+1)))/(Model!$C$8*(1+$A32*Model!$C$9))
A34: Compare every cell to the live do-nothing baseline in B4. HB 1336 falls below do-nothing only where bundling and recovery are simultaneously pessimistic (upper-right corner of the matrix).
A36: Table 4 — Headline rebuttal: "we can only help half as many people" (true do-nothing comparison)
A37: The objection compares two things that are not the alternatives the legislature actually chooses between. The real choice is between current law (no RCD, deposit-only grants) and HB 1336 (RCD permitted, both deposit + RCD refundable to third-party payor under §540-A:7, I(b) and recycled). All HB 1336 figures use the model's current L (Model!C12). r values are explicit per row.
A39: Scenario | B39: Households / 10 yrs | C39: vs. do-nothing | D39: % vs. do-nothing
A40: DO NOTHING (baseline) — grant, deposit-only at current deposit size | B40: =Model!$C$7*10/Model!$C$8 | C40: baseline | D40: —
A41: HB 1336 at the model's current bundle and current r ← live v2.2 defaults | B41: =Model!$C$7/(1-Model!$C$22)*(10-SUMPRODUCT(POWER(Model!$C$22,INT((ROW(INDIRECT("1:10"))-1)/Model!$C$12)+1)))/Model!$C$11 | C41: =B41-$B$4 | D41: =B41/$B$4-1
A42: HB 1336 at current r, 50% bundle | B42: =Model!$C$7/(1-Model!$C$22)*(10-SUMPRODUCT(POWER(Model!$C$22,INT((ROW(INDIRECT("1:10"))-1)/Model!$C$12)+1)))/(Model!$C$8*(1+0.5*Model!$C$9)) | C42: =B42-$B$4 | D42: =B42/$B$4-1
A43: HB 1336 at current r, 100% bundle (worst-case bundling) | B43: =Model!$C$7/(1-Model!$C$22)*(10-SUMPRODUCT(POWER(Model!$C$22,INT((ROW(INDIRECT("1:10"))-1)/Model!$C$12)+1)))/(Model!$C$8*(1+1.0*Model!$C$9)) | C43: =B43-$B$4 | D43: =B43/$B$4-1
A44: HB 1336 at 70% r, 100% bundle (very conservative) | B44: =Model!$C$7/(1-0.7)*(10-SUMPRODUCT(POWER(0.7,INT((ROW(INDIRECT("1:10"))-1)/Model!$C$12)+1)))/(Model!$C$8*(1+1.0*Model!$C$9)) | C44: =B44-$B$4 | D44: =B44/$B$4-1
A45: HB 1336 at 50% r, 50% bundle (deep stress test) | B45: =Model!$C$7/(1-0.5)*(10-SUMPRODUCT(POWER(0.5,INT((ROW(INDIRECT("1:10"))-1)/Model!$C$12)+1)))/(Model!$C$8*(1+0.5*Model!$C$9)) | C45: =B45-$B$4 | D45: =B45/$B$4-1
A47: Bottom line:
A48: At current assumptions the HB 1336 program with bundling outserves the do-nothing baseline by a wide margin. It only falls below the do-nothing baseline when both bundling and recovery are simultaneously pessimistic — a corner case that is neither the central case nor consistent with the TransUnion data. The recycling effect made possible by §540-A:7, I(b) is what flips the bundling penalty from a cost into a net gain.

Sheet Notes & Method
A1: Notes & Method — v2.3 (June 2026, dynamic sensitivity tables)
A3: WHAT THIS MODEL MEASURES
A4: Incremental impact of HB 1336 on what private charitable capital can do for security-deposit assistance.
A5: It compares two worlds, not two charity designs:
A6: Do nothing → current law. RCDs do not exist; charity funds standard deposits as one-way grants at the deposit size set in Model!C8.
A7: HB 1336 passes → charity funds deposit + RCD where needed. Both flow back to the third-party payor under §540-A:7, I(b)
A8: and are recycled into the next household. Capital per assisted hh = deposit × (1 + bundle% × RCD multiple).
A10: METHOD (annual model)
A11: HB 1336 (revolving): capital(t) = net donations + recycle_factor × r × capital(t − L)
A12: Do nothing (grant): capital(t) = net donations every year. Refund flows to tenant; nothing returns to fund. Recovery rate is 0% by definition.
A13: Households(t) under HB 1336 = capital(t) ÷ [deposit × (1 + bundle% × RCD multiple)]
A14: Households(t) under do nothing = capital(t) ÷ deposit (NO RCD term — RCDs do not exist in this world; no recycling)
... A69: Illustrative underwriting model, not a guarantee of outcomes. Real-world recovery and tenancy vary by program design and population.
